[POST] - 200 - 0.01s - /auth/login
[GET]  - 200 - 0.00s - /auth/loginout
[GET]  - 200 - 0.00s - /auth/loginout
Internal Server Error: /auth/loginout
Traceback (most recent call last):
  File "E:\Python\Python39\lib\site-packages\django\core\handlers\exception.py", line 55, in inner
    response = get_response(request)
  File "D:\A7\Desktop\Vulnerabilities_Server\Python_Server\middleware\loggingmiddleware.py", line 20, in __call__
    logger.info("| {} | {: <.2f}s | {: >15}} | {: <6} | {} |".format(response.status_code, duration, client_ip, request.method,  request.path))
ValueError: Single '}' encountered in format string
Internal Server Error: /auth/loginout
Traceback (most recent call last):
  File "E:\Python\Python39\lib\site-packages\django\core\handlers\exception.py", line 55, in inner
    response = get_response(request)
  File "D:\A7\Desktop\Vulnerabilities_Server\Python_Server\middleware\loggingmiddleware.py", line 20, in __call__
    logger.info("| {} | {: <.2f}s | {: >15}} | {: <6} | {} |".format(response.status_code, duration, client_ip, request.method, request.path))
ValueError: Single '}' encountered in format string
Internal Server Error: /auth/loginout
Traceback (most recent call last):
  File "E:\Python\Python39\lib\site-packages\django\core\handlers\exception.py", line 55, in inner
    response = get_response(request)
  File "D:\A7\Desktop\Vulnerabilities_Server\Python_Server\middleware\loggingmiddleware.py", line 21, in __call__
    logger.info("| {} | {: <.2f}s | {: >15}} | {: <6} | {} |".format(response.status_code, duration, client_ip, request.method, request.path))
ValueError: Single '}' encountered in format string
Internal Server Error: /auth/loginout
Traceback (most recent call last):
  File "E:\Python\Python39\lib\site-packages\django\core\handlers\exception.py", line 55, in inner
    response = get_response(request)
  File "D:\A7\Desktop\Vulnerabilities_Server\Python_Server\middleware\loggingmiddleware.py", line 21, in __call__
    logger.info("| {} | {: <.2f}s | {: >15}} | {: <6} | {} |".format(response.status_code, duration, client_ip, request.method, request.path))
ValueError: Single '}' encountered in format string
| 200 | 0.00s |       127.0.0.1 | GET    | /auth/loginout |
| 200 | 0.00s | 127.0.0.1       | GET  | /auth/loginout |
| 200 | 0.01s | 127.0.0.1       | POST | /auth/login |
| 400 | 0.04s | 192.168.31.128  | GET  | /auth/loginout |
Bad Request: /auth/loginout
| 400 | 0.02s | 192.168.31.128  | GET  | /favicon.ico |
Bad Request: /favicon.ico
| 200 | 0.00s | 192.168.31.128  | GET  | /auth/loginout |
| 200 | 0.00s | 192.168.31.128  | GET  | /auth/loginout |
| 404 | 0.03s | 127.0.0.1       | GET  | /as |
Not Found: /as
| 200 | 0.00s | 127.0.0.1       | OPTIONS | /home/getsentence |
| 200 | 0.00s | 127.0.0.1       | OPTIONS | /home/get |
| 200 | 0.02s | 127.0.0.1       | GET  | /home/get |
| 404 | 0.01s | 127.0.0.1       | GET  | //image/qjcrs.png |
Not Found: //image/qjcrs.png
| 200 | 0.14s | 127.0.0.1       | GET  | /static/sentence/sentence.txt |
| 200 | 4.23s | 127.0.0.1       | GET  | /home/getsentence |
| 404 | 0.01s | 127.0.0.1       | GET  | /as |
Not Found: /as
| 200 | 0.01s | 127.0.0.1       | GET  | /home/get |
| 404 | 0.01s | 127.0.0.1       | GET  | //image/qjcrs.png |
Not Found: //image/qjcrs.png
| 200 | 0.00s | 127.0.0.1       | GET  | /static/sentence/sentence.txt |
| 200 | 4.03s | 127.0.0.1       | GET  | /home/getsentence |
| 404 | 0.01s | 127.0.0.1       | GET  | /as |
Not Found: /as
| 200 | 0.01s | 127.0.0.1       | GET  | /home/get |
| 404 | 0.01s | 127.0.0.1       | GET  | //image/qjcrs.png |
Not Found: //image/qjcrs.png
| 200 | 0.00s | 127.0.0.1       | GET  | /static/sentence/sentence.txt |
| 200 | 4.03s | 127.0.0.1       | GET  | /home/getsentence |
| 200 | 0.01s | 127.0.0.1       | GET  | /home/get |
| 404 | 0.01s | 127.0.0.1       | GET  | //image/qjcrs.png |
Not Found: //image/qjcrs.png
| 200 | 0.00s | 127.0.0.1       | GET  | /static/sentence/sentence.txt |
| 200 | 4.02s | 127.0.0.1       | GET  | /home/getsentence |
| 404 | 0.01s | 127.0.0.1       | GET  | /as |
Not Found: /as
| 200 | 0.01s | 127.0.0.1       | GET  | /home/get |
| 404 | 0.01s | 127.0.0.1       | GET  | //image/qjcrs.png |
Not Found: //image/qjcrs.png
| 200 | 0.00s | 127.0.0.1       | GET  | /static/sentence/sentence.txt |
| 200 | 4.02s | 127.0.0.1       | GET  | /home/getsentence |
| 200 | 0.00s | 127.0.0.1       | GET  | /role/get |
| 200 | 0.01s | 127.0.0.1       | POST | /auth/login |
| 200 | 0.00s | 127.0.0.1       | GET  | /role/get |
| 200 | 0.00s | 127.0.0.1       | GET  | /role/get |
| 200 | 0.00s | 127.0.0.1       | GET  | /role/get |
| 200 | 0.01s | 127.0.0.1       | GET  | /role/get |
| 200 | 0.01s | 127.0.0.1       | GET  | /role/get |
| 200 | 0.00s | 127.0.0.1       | GET  | /role/get |
| 200 | 0.01s | 127.0.0.1       | GET  | /role/get |
| 200 | 0.02s | 127.0.0.1       | GET  | /user/get |
| 200 | 0.03s | 127.0.0.1       | GET  | /user/get |
Internal Server Error: /user/get
Traceback (most recent call last):
  File "E:\Python\Python39\lib\site-packages\django\core\handlers\exception.py", line 55, in inner
    response = get_response(request)
  File "E:\Python\Python39\lib\site-packages\django\core\handlers\base.py", line 197, in _get_response
    response = wrapped_callback(request, *callback_args, **callback_kwargs)
  File "E:\Python\Python39\lib\site-packages\django\views\decorators\http.py", line 43, in inner
    return func(request, *args, **kwargs)
  File "D:\A7\Desktop\Vulnerabilities_Server\Python_Server\apps\user\views.py", line 36, in user_get
    print(userlistall.json())
AttributeError: 'QuerySet' object has no attribute 'json'
| 500 | 0.04s | 127.0.0.1       | GET  | /user/get |
Internal Server Error: /user/get
Traceback (most recent call last):
  File "E:\Python\Python39\lib\site-packages\django\core\handlers\exception.py", line 55, in inner
    response = get_response(request)
  File "E:\Python\Python39\lib\site-packages\django\core\handlers\base.py", line 197, in _get_response
    response = wrapped_callback(request, *callback_args, **callback_kwargs)
  File "E:\Python\Python39\lib\site-packages\django\views\decorators\http.py", line 43, in inner
    return func(request, *args, **kwargs)
  File "D:\A7\Desktop\Vulnerabilities_Server\Python_Server\apps\user\views.py", line 36, in user_get
    print(userlistall.json())
AttributeError: 'QuerySet' object has no attribute 'json'
| 500 | 0.03s | 127.0.0.1       | GET  | /user/get |
| 200 | 0.02s | 127.0.0.1       | GET  | /user/get |
| 200 | 0.02s | 127.0.0.1       | GET  | /user/get |
| 200 | 0.01s | 127.0.0.1       | GET  | /user/get |
| 200 | 0.02s | 127.0.0.1       | GET  | /user/get |
Internal Server Error: /user/get
Traceback (most recent call last):
  File "E:\Python\Python39\lib\site-packages\django\core\handlers\exception.py", line 55, in inner
    response = get_response(request)
  File "E:\Python\Python39\lib\site-packages\django\core\handlers\base.py", line 197, in _get_response
    response = wrapped_callback(request, *callback_args, **callback_kwargs)
  File "E:\Python\Python39\lib\site-packages\django\views\decorators\http.py", line 43, in inner
    return func(request, *args, **kwargs)
  File "D:\A7\Desktop\Vulnerabilities_Server\Python_Server\apps\user\views.py", line 36, in user_get
    list(data = serializers.serialize('json', userlistall))
TypeError: list() takes no keyword arguments
| 500 | 0.10s | 127.0.0.1       | GET  | /user/get |
| 200 | 0.01s | 127.0.0.1       | GET  | /user/get |
| 200 | 0.02s | 127.0.0.1       | GET  | /user/get |
| 200 | 0.01s | 127.0.0.1       | GET  | /user/detail |
| 200 | 0.00s | 127.0.0.1       | GET  | /user/detail |
| 200 | 0.00s | 127.0.0.1       | GET  | /user/detail |
| 200 | 0.00s | 127.0.0.1       | OPTIONS | /auth/loginout |
| 200 | 0.00s | 127.0.0.1       | GET  | /auth/loginout |
| 200 | 0.00s | 127.0.0.1       | OPTIONS | /auth/login |
| 200 | 0.05s | 127.0.0.1       | POST | /auth/login |
| 200 | 0.00s | 127.0.0.1       | POST | /auth/login |
| 200 | 0.03s | 127.0.0.1       | POST | /auth/login |
| 200 | 0.04s | 127.0.0.1       | POST | /auth/login |
| 200 | 0.04s | 127.0.0.1       | POST | /auth/login |
| 200 | 0.06s | 127.0.0.1       | POST | /auth/login |
| 200 | 0.00s | 127.0.0.1       | OPTIONS | /home/getsentence |
| 200 | 0.00s | 127.0.0.1       | OPTIONS | /home/get |
| 200 | 0.02s | 127.0.0.1       | GET  | /home/get |
| 404 | 0.02s | 127.0.0.1       | GET  | //image/qjcrs.png |
Not Found: //image/qjcrs.png
| 200 | 0.15s | 127.0.0.1       | GET  | /static/sentence/sentence.txt |
| 200 | 4.24s | 127.0.0.1       | GET  | /home/getsentence |
| 200 | 0.00s | 127.0.0.1       | OPTIONS | /settings/getdb |
| 200 | 0.00s | 127.0.0.1       | POST | /settings/getdb |
| 200 | 0.00s | 127.0.0.1       | OPTIONS | /auth/login |
| 200 | 0.02s | 127.0.0.1       | POST | /auth/login |
| 200 | 0.01s | 127.0.0.1       | GET  | /home/get |
| 404 | 0.02s | 127.0.0.1       | GET  | //image/qjcrs.png |
Not Found: //image/qjcrs.png
| 200 | 0.15s | 127.0.0.1       | GET  | /static/sentence/sentence.txt |
| 200 | 4.23s | 127.0.0.1       | GET  | /home/getsentence |
| 200 | 0.00s | 127.0.0.1       | POST | /settings/getdb |
| 200 | 0.00s | 127.0.0.1       | POST | /settings/getdb |
| 200 | 0.00s | 127.0.0.1       | OPTIONS | /home/updatePwd |
| 200 | 0.00s | 127.0.0.1       | PUT  | /home/updatePwd |
| 200 | 0.00s | 127.0.0.1       | PUT  | /home/updatePwd |
| 200 | 0.00s | 127.0.0.1       | POST | /settings/getdb |
| 200 | 0.00s | 127.0.0.1       | PUT  | /home/updatePwd |
| 200 | 0.00s | 127.0.0.1       | POST | /settings/getdb |
| 200 | 0.00s | 127.0.0.1       | POST | /settings/getdb |
| 200 | 0.00s | 127.0.0.1       | PUT  | /home/updatePwd |
| 200 | 0.00s | 127.0.0.1       | PUT  | /home/updatePwd |
| 200 | 0.02s | 127.0.0.1       | GET  | /home/get |
| 404 | 0.01s | 127.0.0.1       | GET  | //image/qjcrs.png |
Not Found: //image/qjcrs.png
| 200 | 0.00s | 127.0.0.1       | GET  | /static/sentence/sentence.txt |
| 200 | 4.05s | 127.0.0.1       | GET  | /home/getsentence |
| 200 | 0.00s | 127.0.0.1       | PUT  | /home/updatePwd |
| 200 | 0.00s | 127.0.0.1       | PUT  | /home/updatePwd |
| 200 | 0.00s | 127.0.0.1       | PUT  | /home/updatePwd |
| 200 | 0.02s | 127.0.0.1       | GET  | /home/get |
| 404 | 0.01s | 127.0.0.1       | GET  | //image/qjcrs.png |
Not Found: //image/qjcrs.png
| 200 | 0.00s | 127.0.0.1       | GET  | /static/sentence/sentence.txt |
| 200 | 4.08s | 127.0.0.1       | GET  | /home/getsentence |
| 200 | 0.00s | 127.0.0.1       | PUT  | /home/updatePwd |
Internal Server Error: /home/updatePwd
Traceback (most recent call last):
  File "E:\Python\Python39\lib\site-packages\django\core\handlers\exception.py", line 55, in inner
    response = get_response(request)
  File "E:\Python\Python39\lib\site-packages\django\core\handlers\base.py", line 197, in _get_response
    response = wrapped_callback(request, *callback_args, **callback_kwargs)
  File "E:\Python\Python39\lib\site-packages\django\views\decorators\http.py", line 43, in inner
    return func(request, *args, **kwargs)
  File "D:\A7\Desktop\Vulnerabilities_Server\Python_Server\apps\home\views.py", line 69, in home_updatePwd
    plaintext = AES.new("8ffe7-19cbc-4e8-8b33-4d06cf842e2", AES.MODE_CBC, "1cfc13bd74a2").decrypt(data.get("data"))
  File "E:\Python\Python39\lib\site-packages\Crypto\Cipher\AES.py", line 232, in new
    return _create_cipher(sys.modules[__name__], key, mode, *args, **kwargs)
  File "E:\Python\Python39\lib\site-packages\Crypto\Cipher\__init__.py", line 79, in _create_cipher
    return modes[mode](factory, **kwargs)
  File "E:\Python\Python39\lib\site-packages\Crypto\Cipher\_mode_cbc.py", line 274, in _create_cbc_cipher
    cipher_state = factory._create_base_cipher(kwargs)
  File "E:\Python\Python39\lib\site-packages\Crypto\Cipher\AES.py", line 103, in _create_base_cipher
    result = start_operation(c_uint8_ptr(key),
  File "E:\Python\Python39\lib\site-packages\Crypto\Util\_raw_api.py", line 143, in c_uint8_ptr
    raise TypeError("Object type %s cannot be passed to C code" % type(data))
TypeError: Object type <class 'str'> cannot be passed to C code
| 500 | 0.03s | 127.0.0.1       | PUT  | /home/updatePwd |
| 200 | 0.00s | 127.0.0.1       | POST | /settings/getdb |
Internal Server Error: /home/updatePwd
Traceback (most recent call last):
  File "E:\Python\Python39\lib\site-packages\django\core\handlers\exception.py", line 55, in inner
    response = get_response(request)
  File "E:\Python\Python39\lib\site-packages\django\core\handlers\base.py", line 197, in _get_response
    response = wrapped_callback(request, *callback_args, **callback_kwargs)
  File "E:\Python\Python39\lib\site-packages\django\views\decorators\http.py", line 43, in inner
    return func(request, *args, **kwargs)
  File "D:\A7\Desktop\Vulnerabilities_Server\Python_Server\apps\home\views.py", line 69, in home_updatePwd
    plaintext = AES.new("8ffe7-19cbc-4e8-8b33-4d06cf842e2", AES.MODE_CBC, "1cfc13bd74a2").decrypt(data.get("data"))
  File "E:\Python\Python39\lib\site-packages\Crypto\Cipher\AES.py", line 232, in new
    return _create_cipher(sys.modules[__name__], key, mode, *args, **kwargs)
  File "E:\Python\Python39\lib\site-packages\Crypto\Cipher\__init__.py", line 79, in _create_cipher
    return modes[mode](factory, **kwargs)
  File "E:\Python\Python39\lib\site-packages\Crypto\Cipher\_mode_cbc.py", line 274, in _create_cbc_cipher
    cipher_state = factory._create_base_cipher(kwargs)
  File "E:\Python\Python39\lib\site-packages\Crypto\Cipher\AES.py", line 103, in _create_base_cipher
    result = start_operation(c_uint8_ptr(key),
  File "E:\Python\Python39\lib\site-packages\Crypto\Util\_raw_api.py", line 143, in c_uint8_ptr
    raise TypeError("Object type %s cannot be passed to C code" % type(data))
TypeError: Object type <class 'str'> cannot be passed to C code
| 500 | 0.02s | 127.0.0.1       | PUT  | /home/updatePwd |
| 200 | 0.00s | 127.0.0.1       | POST | /settings/getdb |
Internal Server Error: /home/updatePwd
Traceback (most recent call last):
  File "E:\Python\Python39\lib\site-packages\django\core\handlers\exception.py", line 55, in inner
    response = get_response(request)
  File "E:\Python\Python39\lib\site-packages\django\core\handlers\base.py", line 197, in _get_response
    response = wrapped_callback(request, *callback_args, **callback_kwargs)
  File "E:\Python\Python39\lib\site-packages\django\views\decorators\http.py", line 43, in inner
    return func(request, *args, **kwargs)
  File "D:\A7\Desktop\Vulnerabilities_Server\Python_Server\apps\home\views.py", line 69, in home_updatePwd
    plaintext = AES.new("8ffe7-19cbc-4e8-8b33-4d06cf842e2", AES.MODE_CBC, "1cfc13bd74a2").decrypt(data.get("data"))
  File "E:\Python\Python39\lib\site-packages\Crypto\Cipher\AES.py", line 232, in new
    return _create_cipher(sys.modules[__name__], key, mode, *args, **kwargs)
  File "E:\Python\Python39\lib\site-packages\Crypto\Cipher\__init__.py", line 79, in _create_cipher
    return modes[mode](factory, **kwargs)
  File "E:\Python\Python39\lib\site-packages\Crypto\Cipher\_mode_cbc.py", line 274, in _create_cbc_cipher
    cipher_state = factory._create_base_cipher(kwargs)
  File "E:\Python\Python39\lib\site-packages\Crypto\Cipher\AES.py", line 103, in _create_base_cipher
    result = start_operation(c_uint8_ptr(key),
  File "E:\Python\Python39\lib\site-packages\Crypto\Util\_raw_api.py", line 143, in c_uint8_ptr
    raise TypeError("Object type %s cannot be passed to C code" % type(data))
TypeError: Object type <class 'str'> cannot be passed to C code
| 500 | 0.03s | 127.0.0.1       | PUT  | /home/updatePwd |
| 200 | 0.00s | 127.0.0.1       | POST | /settings/getdb |
Internal Server Error: /home/updatePwd
Traceback (most recent call last):
  File "E:\Python\Python39\lib\site-packages\django\core\handlers\exception.py", line 55, in inner
    response = get_response(request)
  File "E:\Python\Python39\lib\site-packages\django\core\handlers\base.py", line 197, in _get_response
    response = wrapped_callback(request, *callback_args, **callback_kwargs)
  File "E:\Python\Python39\lib\site-packages\django\views\decorators\http.py", line 43, in inner
    return func(request, *args, **kwargs)
  File "D:\A7\Desktop\Vulnerabilities_Server\Python_Server\apps\home\views.py", line 70, in home_updatePwd
    plaintext = AES.new("8ffe7-19cbc-4e8-8b33-4d06cf842e2", AES.MODE_CBC, "1cfc13bd74a2").decrypt(data.get("data"))
  File "E:\Python\Python39\lib\site-packages\Crypto\Cipher\AES.py", line 232, in new
    return _create_cipher(sys.modules[__name__], key, mode, *args, **kwargs)
  File "E:\Python\Python39\lib\site-packages\Crypto\Cipher\__init__.py", line 79, in _create_cipher
    return modes[mode](factory, **kwargs)
  File "E:\Python\Python39\lib\site-packages\Crypto\Cipher\_mode_cbc.py", line 274, in _create_cbc_cipher
    cipher_state = factory._create_base_cipher(kwargs)
  File "E:\Python\Python39\lib\site-packages\Crypto\Cipher\AES.py", line 103, in _create_base_cipher
    result = start_operation(c_uint8_ptr(key),
  File "E:\Python\Python39\lib\site-packages\Crypto\Util\_raw_api.py", line 143, in c_uint8_ptr
    raise TypeError("Object type %s cannot be passed to C code" % type(data))
TypeError: Object type <class 'str'> cannot be passed to C code
| 500 | 0.04s | 127.0.0.1       | PUT  | /home/updatePwd |
| 200 | 0.00s | 127.0.0.1       | POST | /settings/getdb |
Internal Server Error: /home/updatePwd
Traceback (most recent call last):
  File "E:\Python\Python39\lib\site-packages\django\core\handlers\exception.py", line 55, in inner
    response = get_response(request)
  File "E:\Python\Python39\lib\site-packages\django\core\handlers\base.py", line 197, in _get_response
    response = wrapped_callback(request, *callback_args, **callback_kwargs)
  File "E:\Python\Python39\lib\site-packages\django\views\decorators\http.py", line 43, in inner
    return func(request, *args, **kwargs)
  File "D:\A7\Desktop\Vulnerabilities_Server\Python_Server\apps\home\views.py", line 70, in home_updatePwd
    plaintext = AES.new("8ffe7-19cbc-4e8-8b33-4d06cf842e2", AES.MODE_CBC, "1cfc13bd74a2").decrypt(data.get("data"))
  File "E:\Python\Python39\lib\site-packages\Crypto\Cipher\AES.py", line 232, in new
    return _create_cipher(sys.modules[__name__], key, mode, *args, **kwargs)
  File "E:\Python\Python39\lib\site-packages\Crypto\Cipher\__init__.py", line 79, in _create_cipher
    return modes[mode](factory, **kwargs)
  File "E:\Python\Python39\lib\site-packages\Crypto\Cipher\_mode_cbc.py", line 274, in _create_cbc_cipher
    cipher_state = factory._create_base_cipher(kwargs)
  File "E:\Python\Python39\lib\site-packages\Crypto\Cipher\AES.py", line 103, in _create_base_cipher
    result = start_operation(c_uint8_ptr(key),
  File "E:\Python\Python39\lib\site-packages\Crypto\Util\_raw_api.py", line 143, in c_uint8_ptr
    raise TypeError("Object type %s cannot be passed to C code" % type(data))
TypeError: Object type <class 'str'> cannot be passed to C code
| 500 | 0.04s | 127.0.0.1       | PUT  | /home/updatePwd |
| 200 | 0.00s | 127.0.0.1       | POST | /settings/getdb |
| 200 | 0.00s | 127.0.0.1       | PUT  | /home/updatePwd |
| 200 | 0.00s | 127.0.0.1       | OPTIONS | /home/updatePwd |
| 200 | 0.00s | 127.0.0.1       | PUT  | /home/updatePwd |
| 200 | 0.00s | 127.0.0.1       | PUT  | /home/updatePwd |
| 200 | 0.00s | 127.0.0.1       | PUT  | /home/updatePwd |
| 200 | 0.00s | 127.0.0.1       | POST | /settings/getdb |
| 200 | 0.00s | 127.0.0.1       | PUT  | /home/updatePwd |
| 200 | 0.00s | 127.0.0.1       | PUT  | /home/updatePwd |
| 200 | 0.00s | 127.0.0.1       | PUT  | /home/updatePwd |
| 200 | 0.00s | 127.0.0.1       | OPTIONS | /settings/getdb |
| 200 | 0.00s | 127.0.0.1       | POST | /settings/getdb |
| 200 | 0.00s | 127.0.0.1       | OPTIONS | /home/updatePwd |
| 200 | 0.01s | 127.0.0.1       | PUT  | /home/updatePwd |
| 200 | 0.00s | 127.0.0.1       | OPTIONS | /home/updatePwd |
| 200 | 0.00s | 127.0.0.1       | PUT  | /home/updatePwd |
| 200 | 0.00s | 127.0.0.1       | OPTIONS | /settings/getdb |
| 200 | 0.00s | 127.0.0.1       | POST | /settings/getdb |
| 200 | 0.00s | 127.0.0.1       | OPTIONS | /user/get |
| 200 | 0.00s | 127.0.0.1       | GET  | /user/get |
| 200 | 0.00s | 127.0.0.1       | GET  | /user/get |
| 200 | 0.00s | 127.0.0.1       | GET  | /auth/loginout |
| 200 | 0.01s | 127.0.0.1       | POST | /auth/login |
| 200 | 0.00s | 127.0.0.1       | OPTIONS | /home/getsentence |
| 200 | 0.00s | 127.0.0.1       | OPTIONS | /home/get |
| 200 | 0.01s | 127.0.0.1       | GET  | /home/get |
| 404 | 0.02s | 127.0.0.1       | GET  | //image/qjcrs.png |
Not Found: //image/qjcrs.png
Internal Server Error: /user/get
Traceback (most recent call last):
  File "E:\Python\Python39\lib\site-packages\django\core\handlers\exception.py", line 55, in inner
    response = get_response(request)
  File "E:\Python\Python39\lib\site-packages\django\core\handlers\base.py", line 197, in _get_response
    response = wrapped_callback(request, *callback_args, **callback_kwargs)
  File "E:\Python\Python39\lib\site-packages\django\views\decorators\http.py", line 43, in inner
    return func(request, *args, **kwargs)
  File "D:\A7\Desktop\Vulnerabilities_Server\Python_Server\apps\user\views.py", line 45, in user_get
    ciphertext = helper.RsaEncrypt(result)
  File "D:\A7\Desktop\Vulnerabilities_Server\Python_Server\common\helper.py", line 169, in RsaEncrypt
    ciphertext = cipher_rsa_encrypt.encrypt(plaintext.encode())
AttributeError: 'dict' object has no attribute 'encode'
| 500 | 0.12s | 127.0.0.1       | GET  | /user/get |
| 200 | 0.15s | 127.0.0.1       | GET  | /static/sentence/sentence.txt |
| 200 | 4.26s | 127.0.0.1       | GET  | /home/getsentence |
| 200 | 0.00s | 127.0.0.1       | OPTIONS | /role/get |
| 200 | 0.01s | 127.0.0.1       | GET  | /role/get |
Internal Server Error: /user/get
Traceback (most recent call last):
  File "E:\Python\Python39\lib\site-packages\django\core\handlers\exception.py", line 55, in inner
    response = get_response(request)
  File "E:\Python\Python39\lib\site-packages\django\core\handlers\base.py", line 197, in _get_response
    response = wrapped_callback(request, *callback_args, **callback_kwargs)
  File "E:\Python\Python39\lib\site-packages\django\views\decorators\http.py", line 43, in inner
    return func(request, *args, **kwargs)
  File "D:\A7\Desktop\Vulnerabilities_Server\Python_Server\apps\user\views.py", line 45, in user_get
    ciphertext = helper.RsaEncrypt(result)
  File "D:\A7\Desktop\Vulnerabilities_Server\Python_Server\common\helper.py", line 169, in RsaEncrypt
    ciphertext = cipher_rsa_encrypt.encrypt(plaintext.encode())
AttributeError: 'dict' object has no attribute 'encode'
| 500 | 0.07s | 127.0.0.1       | GET  | /user/get |
| 200 | 0.02s | 127.0.0.1       | GET  | /role/get |
Internal Server Error: /user/get
Traceback (most recent call last):
  File "E:\Python\Python39\lib\site-packages\django\core\handlers\exception.py", line 55, in inner
    response = get_response(request)
  File "E:\Python\Python39\lib\site-packages\django\core\handlers\base.py", line 197, in _get_response
    response = wrapped_callback(request, *callback_args, **callback_kwargs)
  File "E:\Python\Python39\lib\site-packages\django\views\decorators\http.py", line 43, in inner
    return func(request, *args, **kwargs)
  File "D:\A7\Desktop\Vulnerabilities_Server\Python_Server\apps\user\views.py", line 45, in user_get
    ciphertext = helper.RsaEncrypt(result)
  File "D:\A7\Desktop\Vulnerabilities_Server\Python_Server\common\helper.py", line 169, in RsaEncrypt
    ciphertext = cipher_rsa_encrypt.encrypt(plaintext.encode())
AttributeError: 'dict' object has no attribute 'encode'
| 500 | 0.12s | 127.0.0.1       | GET  | /user/get |
| 200 | 0.01s | 127.0.0.1       | GET  | /role/get |
Internal Server Error: /user/get
Traceback (most recent call last):
  File "E:\Python\Python39\lib\site-packages\django\core\handlers\exception.py", line 55, in inner
    response = get_response(request)
  File "E:\Python\Python39\lib\site-packages\django\core\handlers\base.py", line 197, in _get_response
    response = wrapped_callback(request, *callback_args, **callback_kwargs)
  File "E:\Python\Python39\lib\site-packages\django\views\decorators\http.py", line 43, in inner
    return func(request, *args, **kwargs)
  File "D:\A7\Desktop\Vulnerabilities_Server\Python_Server\apps\user\views.py", line 44, in user_get
    ciphertext = helper.RsaEncrypt(str(result))
  File "D:\A7\Desktop\Vulnerabilities_Server\Python_Server\common\helper.py", line 169, in RsaEncrypt
    ciphertext = cipher_rsa_encrypt.encrypt(plaintext.encode())
  File "E:\Python\Python39\lib\site-packages\Crypto\Cipher\PKCS1_OAEP.py", line 115, in encrypt
    raise ValueError("Plaintext is too long.")
ValueError: Plaintext is too long.
| 500 | 0.08s | 127.0.0.1       | GET  | /user/get |
| 200 | 0.01s | 127.0.0.1       | GET  | /role/get |
Internal Server Error: /user/get
Traceback (most recent call last):
  File "E:\Python\Python39\lib\site-packages\django\core\handlers\exception.py", line 55, in inner
    response = get_response(request)
  File "E:\Python\Python39\lib\site-packages\django\core\handlers\base.py", line 197, in _get_response
    response = wrapped_callback(request, *callback_args, **callback_kwargs)
  File "E:\Python\Python39\lib\site-packages\django\views\decorators\http.py", line 43, in inner
    return func(request, *args, **kwargs)
  File "D:\A7\Desktop\Vulnerabilities_Server\Python_Server\apps\user\views.py", line 44, in user_get
    ciphertext = helper.RsaEncrypt(str(result))
  File "D:\A7\Desktop\Vulnerabilities_Server\Python_Server\common\helper.py", line 170, in RsaEncrypt
    ciphertext = cipher_rsa_encrypt.encrypt(plaintext.encode())
  File "E:\Python\Python39\lib\site-packages\Crypto\Cipher\PKCS1_OAEP.py", line 115, in encrypt
    raise ValueError("Plaintext is too long.")
ValueError: Plaintext is too long.
| 500 | 0.08s | 127.0.0.1       | GET  | /user/get |
| 200 | 0.01s | 127.0.0.1       | GET  | /role/get |
Internal Server Error: /user/get
Traceback (most recent call last):
  File "E:\Python\Python39\lib\site-packages\django\core\handlers\exception.py", line 55, in inner
    response = get_response(request)
  File "E:\Python\Python39\lib\site-packages\django\core\handlers\base.py", line 197, in _get_response
    response = wrapped_callback(request, *callback_args, **callback_kwargs)
  File "E:\Python\Python39\lib\site-packages\django\views\decorators\http.py", line 43, in inner
    return func(request, *args, **kwargs)
  File "D:\A7\Desktop\Vulnerabilities_Server\Python_Server\apps\user\views.py", line 44, in user_get
    ciphertext = helper.RsaEncrypt(str(result))
  File "D:\A7\Desktop\Vulnerabilities_Server\Python_Server\common\helper.py", line 170, in RsaEncrypt
    ciphertext = cipher_rsa_encrypt.encrypt(plaintext.encode())
  File "E:\Python\Python39\lib\site-packages\Crypto\Cipher\PKCS1_OAEP.py", line 115, in encrypt
    raise ValueError("Plaintext is too long.")
ValueError: Plaintext is too long.
| 500 | 0.07s | 127.0.0.1       | GET  | /user/get |
| 200 | 0.01s | 127.0.0.1       | GET  | /role/get |
Internal Server Error: /user/get
Traceback (most recent call last):
  File "E:\Python\Python39\lib\site-packages\django\core\handlers\exception.py", line 55, in inner
    response = get_response(request)
  File "E:\Python\Python39\lib\site-packages\django\core\handlers\base.py", line 197, in _get_response
    response = wrapped_callback(request, *callback_args, **callback_kwargs)
  File "E:\Python\Python39\lib\site-packages\django\views\decorators\http.py", line 43, in inner
    return func(request, *args, **kwargs)
  File "D:\A7\Desktop\Vulnerabilities_Server\Python_Server\apps\user\views.py", line 44, in user_get
    ciphertext = helper.RsaEncrypt(str(result))
  File "D:\A7\Desktop\Vulnerabilities_Server\Python_Server\common\helper.py", line 170, in RsaEncrypt
    ciphertext = cipher_rsa_encrypt.encrypt(plaintext.encode())
  File "E:\Python\Python39\lib\site-packages\Crypto\Cipher\PKCS1_OAEP.py", line 115, in encrypt
    raise ValueError("Plaintext is too long.")
ValueError: Plaintext is too long.
| 500 | 0.06s | 127.0.0.1       | GET  | /user/get |
| 200 | 0.01s | 127.0.0.1       | GET  | /role/get |
Internal Server Error: /user/get
Traceback (most recent call last):
  File "E:\Python\Python39\lib\site-packages\django\core\handlers\exception.py", line 55, in inner
    response = get_response(request)
  File "E:\Python\Python39\lib\site-packages\django\core\handlers\base.py", line 197, in _get_response
    response = wrapped_callback(request, *callback_args, **callback_kwargs)
  File "E:\Python\Python39\lib\site-packages\django\views\decorators\http.py", line 43, in inner
    return func(request, *args, **kwargs)
  File "D:\A7\Desktop\Vulnerabilities_Server\Python_Server\apps\user\views.py", line 44, in user_get
    ciphertext = helper.RsaEncrypt(str(result))
  File "D:\A7\Desktop\Vulnerabilities_Server\Python_Server\common\helper.py", line 169, in RsaEncrypt
    ciphertext = cipher_rsa_encrypt.encrypt(plaintext.encode())
  File "E:\Python\Python39\lib\site-packages\Crypto\Cipher\PKCS1_OAEP.py", line 115, in encrypt
    raise ValueError("Plaintext is too long.")
ValueError: Plaintext is too long.
| 500 | 0.08s | 127.0.0.1       | GET  | /user/get |
| 200 | 0.01s | 127.0.0.1       | GET  | /role/get |
Internal Server Error: /user/get
Traceback (most recent call last):
  File "E:\Python\Python39\lib\site-packages\django\core\handlers\exception.py", line 55, in inner
    response = get_response(request)
  File "E:\Python\Python39\lib\site-packages\django\core\handlers\base.py", line 197, in _get_response
    response = wrapped_callback(request, *callback_args, **callback_kwargs)
  File "E:\Python\Python39\lib\site-packages\django\views\decorators\http.py", line 43, in inner
    return func(request, *args, **kwargs)
  File "D:\A7\Desktop\Vulnerabilities_Server\Python_Server\apps\user\views.py", line 44, in user_get
    ciphertext = helper.RsaEncrypt(str(result))
  File "D:\A7\Desktop\Vulnerabilities_Server\Python_Server\common\helper.py", line 169, in RsaEncrypt
    ciphertext = cipher_rsa_encrypt.encrypt(plaintext)
  File "E:\Python\Python39\lib\site-packages\Crypto\Cipher\PKCS1_OAEP.py", line 115, in encrypt
    raise ValueError("Plaintext is too long.")
ValueError: Plaintext is too long.
| 500 | 0.09s | 127.0.0.1       | GET  | /user/get |
Internal Server Error: /user/get
Traceback (most recent call last):
  File "E:\Python\Python39\lib\site-packages\django\core\handlers\exception.py", line 55, in inner
    response = get_response(request)
  File "E:\Python\Python39\lib\site-packages\django\core\handlers\base.py", line 197, in _get_response
    response = wrapped_callback(request, *callback_args, **callback_kwargs)
  File "E:\Python\Python39\lib\site-packages\django\views\decorators\http.py", line 43, in inner
    return func(request, *args, **kwargs)
  File "D:\A7\Desktop\Vulnerabilities_Server\Python_Server\apps\user\views.py", line 44, in user_get
    ciphertext = helper.RsaEncrypt(str(result))
  File "D:\A7\Desktop\Vulnerabilities_Server\Python_Server\common\helper.py", line 170, in RsaEncrypt
    ciphertext = cipher_rsa_encrypt.encrypt(plaintext.encode())
  File "E:\Python\Python39\lib\site-packages\Crypto\Cipher\PKCS1_OAEP.py", line 115, in encrypt
    raise ValueError("Plaintext is too long.")
ValueError: Plaintext is too long.
| 500 | 0.11s | 127.0.0.1       | GET  | /user/get |
| 200 | 0.01s | 127.0.0.1       | GET  | /role/get |
Internal Server Error: /user/get
Traceback (most recent call last):
  File "E:\Python\Python39\lib\site-packages\django\core\handlers\exception.py", line 55, in inner
    response = get_response(request)
  File "E:\Python\Python39\lib\site-packages\django\core\handlers\base.py", line 197, in _get_response
    response = wrapped_callback(request, *callback_args, **callback_kwargs)
  File "E:\Python\Python39\lib\site-packages\django\views\decorators\http.py", line 43, in inner
    return func(request, *args, **kwargs)
  File "D:\A7\Desktop\Vulnerabilities_Server\Python_Server\apps\user\views.py", line 44, in user_get
    ciphertext = helper.RsaEncrypt(json.dumps(result))
  File "E:\Python\Python39\lib\json\__init__.py", line 231, in dumps
    return _default_encoder.encode(obj)
  File "E:\Python\Python39\lib\json\encoder.py", line 199, in encode
    chunks = self.iterencode(o, _one_shot=True)
  File "E:\Python\Python39\lib\json\encoder.py", line 257, in iterencode
    return _iterencode(o, 0)
  File "E:\Python\Python39\lib\json\encoder.py", line 179, in default
    raise TypeError(f'Object of type {o.__class__.__name__} '
TypeError: Object of type datetime is not JSON serializable
| 500 | 0.11s | 127.0.0.1       | GET  | /user/get |
| 200 | 0.01s | 127.0.0.1       | GET  | /role/get |
Internal Server Error: /user/get
Traceback (most recent call last):
  File "E:\Python\Python39\lib\site-packages\django\core\handlers\exception.py", line 55, in inner
    response = get_response(request)
  File "E:\Python\Python39\lib\site-packages\django\core\handlers\base.py", line 197, in _get_response
    response = wrapped_callback(request, *callback_args, **callback_kwargs)
  File "E:\Python\Python39\lib\site-packages\django\views\decorators\http.py", line 43, in inner
    return func(request, *args, **kwargs)
  File "D:\A7\Desktop\Vulnerabilities_Server\Python_Server\apps\user\views.py", line 44, in user_get
    ciphertext = helper.RsaEncrypt(json.dumps(result))
  File "E:\Python\Python39\lib\json\__init__.py", line 231, in dumps
    return _default_encoder.encode(obj)
  File "E:\Python\Python39\lib\json\encoder.py", line 199, in encode
    chunks = self.iterencode(o, _one_shot=True)
  File "E:\Python\Python39\lib\json\encoder.py", line 257, in iterencode
    return _iterencode(o, 0)
  File "E:\Python\Python39\lib\json\encoder.py", line 179, in default
    raise TypeError(f'Object of type {o.__class__.__name__} '
TypeError: Object of type datetime is not JSON serializable
| 500 | 0.09s | 127.0.0.1       | GET  | /user/get |
| 200 | 0.00s | 127.0.0.1       | POST | /settings/getdb |
Internal Server Error: /user/get
Traceback (most recent call last):
  File "E:\Python\Python39\lib\site-packages\django\core\handlers\exception.py", line 55, in inner
    response = get_response(request)
  File "E:\Python\Python39\lib\site-packages\django\core\handlers\base.py", line 197, in _get_response
    response = wrapped_callback(request, *callback_args, **callback_kwargs)
  File "E:\Python\Python39\lib\site-packages\django\views\decorators\http.py", line 43, in inner
    return func(request, *args, **kwargs)
  File "D:\A7\Desktop\Vulnerabilities_Server\Python_Server\apps\user\views.py", line 43, in user_get
    print(json.dumps(result))
  File "E:\Python\Python39\lib\json\__init__.py", line 231, in dumps
    return _default_encoder.encode(obj)
  File "E:\Python\Python39\lib\json\encoder.py", line 199, in encode
    chunks = self.iterencode(o, _one_shot=True)
  File "E:\Python\Python39\lib\json\encoder.py", line 257, in iterencode
    return _iterencode(o, 0)
  File "E:\Python\Python39\lib\json\encoder.py", line 179, in default
    raise TypeError(f'Object of type {o.__class__.__name__} '
TypeError: Object of type datetime is not JSON serializable
| 500 | 0.07s | 127.0.0.1       | GET  | /user/get |
| 200 | 0.01s | 127.0.0.1       | GET  | /role/get |
Internal Server Error: /user/get
Traceback (most recent call last):
  File "E:\Python\Python39\lib\site-packages\django\core\handlers\exception.py", line 55, in inner
    response = get_response(request)
  File "E:\Python\Python39\lib\site-packages\django\core\handlers\base.py", line 197, in _get_response
    response = wrapped_callback(request, *callback_args, **callback_kwargs)
  File "E:\Python\Python39\lib\site-packages\django\views\decorators\http.py", line 43, in inner
    return func(request, *args, **kwargs)
  File "D:\A7\Desktop\Vulnerabilities_Server\Python_Server\apps\user\views.py", line 43, in user_get
    print(json.dumps(result))
  File "E:\Python\Python39\lib\json\__init__.py", line 231, in dumps
    return _default_encoder.encode(obj)
  File "E:\Python\Python39\lib\json\encoder.py", line 199, in encode
    chunks = self.iterencode(o, _one_shot=True)
  File "E:\Python\Python39\lib\json\encoder.py", line 257, in iterencode
    return _iterencode(o, 0)
  File "E:\Python\Python39\lib\json\encoder.py", line 179, in default
    raise TypeError(f'Object of type {o.__class__.__name__} '
TypeError: Object of type datetime is not JSON serializable
| 500 | 0.07s | 127.0.0.1       | GET  | /user/get |
| 200 | 0.01s | 127.0.0.1       | GET  | /role/get |
Internal Server Error: /user/get
Traceback (most recent call last):
  File "E:\Python\Python39\lib\site-packages\django\core\handlers\exception.py", line 55, in inner
    response = get_response(request)
  File "E:\Python\Python39\lib\site-packages\django\core\handlers\base.py", line 197, in _get_response
    response = wrapped_callback(request, *callback_args, **callback_kwargs)
  File "E:\Python\Python39\lib\site-packages\django\views\decorators\http.py", line 43, in inner
    return func(request, *args, **kwargs)
  File "D:\A7\Desktop\Vulnerabilities_Server\Python_Server\apps\user\views.py", line 44, in user_get
    ciphertext = helper.RsaEncrypt(repr(result))
  File "D:\A7\Desktop\Vulnerabilities_Server\Python_Server\common\helper.py", line 170, in RsaEncrypt
    ciphertext = cipher_rsa_encrypt.encrypt(plaintext.encode())
  File "E:\Python\Python39\lib\site-packages\Crypto\Cipher\PKCS1_OAEP.py", line 115, in encrypt
    raise ValueError("Plaintext is too long.")
ValueError: Plaintext is too long.
| 500 | 0.11s | 127.0.0.1       | GET  | /user/get |
| 200 | 0.01s | 127.0.0.1       | GET  | /role/get |
Internal Server Error: /user/get
Traceback (most recent call last):
  File "E:\Python\Python39\lib\site-packages\django\core\handlers\exception.py", line 55, in inner
    response = get_response(request)
  File "E:\Python\Python39\lib\site-packages\django\core\handlers\base.py", line 197, in _get_response
    response = wrapped_callback(request, *callback_args, **callback_kwargs)
  File "E:\Python\Python39\lib\site-packages\django\views\decorators\http.py", line 43, in inner
    return func(request, *args, **kwargs)
  File "D:\A7\Desktop\Vulnerabilities_Server\Python_Server\apps\user\views.py", line 44, in user_get
    ciphertext = helper.RsaEncrypt(repr(result))
  File "D:\A7\Desktop\Vulnerabilities_Server\Python_Server\common\helper.py", line 170, in RsaEncrypt
    ciphertext = cipher_rsa_encrypt.encrypt(aaa.encode())
  File "E:\Python\Python39\lib\site-packages\Crypto\Cipher\PKCS1_OAEP.py", line 115, in encrypt
    raise ValueError("Plaintext is too long.")
ValueError: Plaintext is too long.
| 500 | 0.07s | 127.0.0.1       | GET  | /user/get |
| 200 | 0.01s | 127.0.0.1       | GET  | /role/get |
| 200 | 0.03s | 127.0.0.1       | GET  | /user/get |
| 200 | 0.02s | 127.0.0.1       | GET  | /user/get |
| 200 | 0.01s | 127.0.0.1       | GET  | /role/get |
Internal Server Error: /user/get
Traceback (most recent call last):
  File "E:\Python\Python39\lib\site-packages\django\core\handlers\exception.py", line 55, in inner
    response = get_response(request)
  File "E:\Python\Python39\lib\site-packages\django\core\handlers\base.py", line 197, in _get_response
    response = wrapped_callback(request, *callback_args, **callback_kwargs)
  File "E:\Python\Python39\lib\site-packages\django\views\decorators\http.py", line 43, in inner
    return func(request, *args, **kwargs)
  File "D:\A7\Desktop\Vulnerabilities_Server\Python_Server\apps\user\views.py", line 39, in user_get
    result = "{'count': "+cnt+",'list': "+userlisttmp[(Page-1)*Size:Page*Size]+",}"
TypeError: can only concatenate str (not "int") to str
| 500 | 0.06s | 127.0.0.1       | GET  | /user/get |
| 200 | 0.01s | 127.0.0.1       | GET  | /role/get |
Internal Server Error: /user/get
Traceback (most recent call last):
  File "E:\Python\Python39\lib\site-packages\django\core\handlers\exception.py", line 55, in inner
    response = get_response(request)
  File "E:\Python\Python39\lib\site-packages\django\core\handlers\base.py", line 197, in _get_response
    response = wrapped_callback(request, *callback_args, **callback_kwargs)
  File "E:\Python\Python39\lib\site-packages\django\views\decorators\http.py", line 43, in inner
    return func(request, *args, **kwargs)
  File "D:\A7\Desktop\Vulnerabilities_Server\Python_Server\apps\user\views.py", line 39, in user_get
    result = "{'count': "+cnt+",'list': "+userlisttmp[(Page-1)*Size:Page*Size]+"}"
TypeError: can only concatenate str (not "int") to str
| 500 | 0.05s | 127.0.0.1       | GET  | /user/get |
| 200 | 0.01s | 127.0.0.1       | GET  | /role/get |
Internal Server Error: /user/get
Traceback (most recent call last):
  File "E:\Python\Python39\lib\site-packages\django\core\handlers\exception.py", line 55, in inner
    response = get_response(request)
  File "E:\Python\Python39\lib\site-packages\django\core\handlers\base.py", line 197, in _get_response
    response = wrapped_callback(request, *callback_args, **callback_kwargs)
  File "E:\Python\Python39\lib\site-packages\django\views\decorators\http.py", line 43, in inner
    return func(request, *args, **kwargs)
  File "D:\A7\Desktop\Vulnerabilities_Server\Python_Server\apps\user\views.py", line 39, in user_get
    result = "{'count': "+cnt+",'list': "+userlisttmp[(Page-1)*Size:Page*Size]+"}"
TypeError: can only concatenate str (not "int") to str
| 500 | 0.07s | 127.0.0.1       | GET  | /user/get |
| 200 | 0.01s | 127.0.0.1       | GET  | /role/get |
Internal Server Error: /user/get
Traceback (most recent call last):
  File "E:\Python\Python39\lib\site-packages\django\core\handlers\exception.py", line 55, in inner
    response = get_response(request)
  File "E:\Python\Python39\lib\site-packages\django\core\handlers\base.py", line 197, in _get_response
    response = wrapped_callback(request, *callback_args, **callback_kwargs)
  File "E:\Python\Python39\lib\site-packages\django\views\decorators\http.py", line 43, in inner
    return func(request, *args, **kwargs)
  File "D:\A7\Desktop\Vulnerabilities_Server\Python_Server\apps\user\views.py", line 39, in user_get
    result = "{'count': "+cnt+",'list': }"
TypeError: can only concatenate str (not "int") to str
| 500 | 0.05s | 127.0.0.1       | GET  | /user/get |
| 200 | 0.01s | 127.0.0.1       | GET  | /role/get |
| 200 | 0.04s | 127.0.0.1       | GET  | /user/get |
| 200 | 0.03s | 127.0.0.1       | GET  | /user/get |
| 200 | 0.01s | 127.0.0.1       | GET  | /role/get |
| 200 | 0.03s | 127.0.0.1       | GET  | /user/get |
| 200 | 0.02s | 127.0.0.1       | GET  | /user/get |
| 200 | 0.01s | 127.0.0.1       | GET  | /role/get |
Internal Server Error: /user/get
Traceback (most recent call last):
  File "E:\Python\Python39\lib\site-packages\django\core\handlers\exception.py", line 55, in inner
    response = get_response(request)
  File "E:\Python\Python39\lib\site-packages\django\core\handlers\base.py", line 197, in _get_response
    response = wrapped_callback(request, *callback_args, **callback_kwargs)
  File "E:\Python\Python39\lib\site-packages\django\views\decorators\http.py", line 43, in inner
    return func(request, *args, **kwargs)
  File "D:\A7\Desktop\Vulnerabilities_Server\Python_Server\apps\user\views.py", line 39, in user_get
    result = "\{'count': {},'list': {}\}".format(cnt,userlisttmp[(Page-1)*Size:Page*Size])
KeyError: "'count'"
| 500 | 0.05s | 127.0.0.1       | GET  | /user/get |
| 200 | 0.01s | 127.0.0.1       | GET  | /role/get |
Internal Server Error: /user/get
Traceback (most recent call last):
  File "E:\Python\Python39\lib\site-packages\django\core\handlers\exception.py", line 55, in inner
    response = get_response(request)
  File "E:\Python\Python39\lib\site-packages\django\core\handlers\base.py", line 197, in _get_response
    response = wrapped_callback(request, *callback_args, **callback_kwargs)
  File "E:\Python\Python39\lib\site-packages\django\views\decorators\http.py", line 43, in inner
    return func(request, *args, **kwargs)
  File "D:\A7\Desktop\Vulnerabilities_Server\Python_Server\apps\user\views.py", line 39, in user_get
    result = "\{'count': {},'list': {}\}".format(cnt,''.join(userlisttmp[(Page-1)*Size:Page*Size]))
TypeError: sequence item 0: expected str instance, dict found
| 500 | 0.05s | 127.0.0.1       | GET  | /user/get |
| 200 | 0.01s | 127.0.0.1       | GET  | /role/get |
Internal Server Error: /user/get
Traceback (most recent call last):
  File "E:\Python\Python39\lib\site-packages\django\core\handlers\exception.py", line 55, in inner
    response = get_response(request)
  File "E:\Python\Python39\lib\site-packages\django\core\handlers\base.py", line 197, in _get_response
    response = wrapped_callback(request, *callback_args, **callback_kwargs)
  File "E:\Python\Python39\lib\site-packages\django\views\decorators\http.py", line 43, in inner
    return func(request, *args, **kwargs)
  File "D:\A7\Desktop\Vulnerabilities_Server\Python_Server\apps\user\views.py", line 43, in user_get
    type(result)
UnboundLocalError: local variable 'result' referenced before assignment
| 500 | 0.07s | 127.0.0.1       | GET  | /user/get |
| 200 | 0.02s | 127.0.0.1       | GET  | /user/get |
| 200 | 0.01s | 127.0.0.1       | GET  | /role/get |
| 200 | 0.01s | 127.0.0.1       | GET  | /user/get |
| 200 | 0.01s | 127.0.0.1       | GET  | /role/get |
| 200 | 0.01s | 127.0.0.1       | GET  | /user/get |
| 200 | 0.01s | 127.0.0.1       | GET  | /role/get |
| 200 | 0.01s | 127.0.0.1       | GET  | /user/get |
| 301 | 0.00s | 127.0.0.1       | GET  | /swagger |
Internal Server Error: /swagger/
Traceback (most recent call last):
  File "E:\Python\Python39\lib\site-packages\django\core\handlers\exception.py", line 47, in inner
    response = get_response(request)
  File "E:\Python\Python39\lib\site-packages\django\core\handlers\base.py", line 181, in _get_response
    response = wrapped_callback(request, *callback_args, **callback_kwargs)
  File "E:\Python\Python39\lib\site-packages\django\views\decorators\csrf.py", line 54, in wrapped_view
    return view_func(*args, **kwargs)
  File "E:\Python\Python39\lib\site-packages\django\views\generic\base.py", line 70, in view
    return self.dispatch(request, *args, **kwargs)
  File "E:\Python\Python39\lib\site-packages\rest_framework\views.py", line 509, in dispatch
    response = self.handle_exception(exc)
  File "E:\Python\Python39\lib\site-packages\rest_framework\views.py", line 469, in handle_exception
    self.raise_uncaught_exception(exc)
  File "E:\Python\Python39\lib\site-packages\rest_framework\views.py", line 480, in raise_uncaught_exception
    raise exc
  File "E:\Python\Python39\lib\site-packages\rest_framework\views.py", line 497, in dispatch
    self.initial(request, *args, **kwargs)
  File "E:\Python\Python39\lib\site-packages\rest_framework\views.py", line 414, in initial
    self.perform_authentication(request)
  File "E:\Python\Python39\lib\site-packages\rest_framework\views.py", line 324, in perform_authentication
    request.user
  File "E:\Python\Python39\lib\site-packages\rest_framework\request.py", line 227, in user
    self._authenticate()
  File "E:\Python\Python39\lib\site-packages\rest_framework\request.py", line 390, in _authenticate
    self._not_authenticated()
  File "E:\Python\Python39\lib\site-packages\rest_framework\request.py", line 400, in _not_authenticated
    if api_settings.UNAUTHENTICATED_USER:
  File "E:\Python\Python39\lib\site-packages\rest_framework\settings.py", line 225, in __getattr__
    val = perform_import(val, attr)
  File "E:\Python\Python39\lib\site-packages\rest_framework\settings.py", line 166, in perform_import
    return import_from_string(val, setting_name)
  File "E:\Python\Python39\lib\site-packages\rest_framework\settings.py", line 177, in import_from_string
    return import_string(val)
  File "E:\Python\Python39\lib\site-packages\django\utils\module_loading.py", line 17, in import_string
    module = import_module(module_path)
  File "E:\Python\Python39\lib\importlib\__init__.py", line 127, in import_module
    return _bootstrap._gcd_import(name[level:], package, level)
  File "<frozen importlib._bootstrap>", line 1030, in _gcd_import
  File "<frozen importlib._bootstrap>", line 1007, in _find_and_load
  File "<frozen importlib._bootstrap>", line 986, in _find_and_load_unlocked
  File "<frozen importlib._bootstrap>", line 680, in _load_unlocked
  File "<frozen importlib._bootstrap_external>", line 850, in exec_module
  File "<frozen importlib._bootstrap>", line 228, in _call_with_frames_removed
  File "E:\Python\Python39\lib\site-packages\django\contrib\auth\models.py", line 5, in <module>
    from django.contrib.contenttypes.models import ContentType
  File "E:\Python\Python39\lib\site-packages\django\contrib\contenttypes\models.py", line 133, in <module>
    class ContentType(models.Model):
  File "E:\Python\Python39\lib\site-packages\django\db\models\base.py", line 113, in __new__
    raise RuntimeError(
RuntimeError: Model class django.contrib.contenttypes.models.ContentType doesn't declare an explicit app_label and isn't in an application in INSTALLED_APPS.
| 500 | 0.07s | 127.0.0.1       | GET  | /swagger/ |
Internal Server Error: /swagger/
Traceback (most recent call last):
  File "E:\Python\Python39\lib\site-packages\django\core\handlers\exception.py", line 47, in inner
    response = get_response(request)
  File "E:\Python\Python39\lib\site-packages\django\core\handlers\base.py", line 181, in _get_response
    response = wrapped_callback(request, *callback_args, **callback_kwargs)
  File "E:\Python\Python39\lib\site-packages\django\views\decorators\csrf.py", line 54, in wrapped_view
    return view_func(*args, **kwargs)
  File "E:\Python\Python39\lib\site-packages\django\views\generic\base.py", line 70, in view
    return self.dispatch(request, *args, **kwargs)
  File "E:\Python\Python39\lib\site-packages\rest_framework\views.py", line 509, in dispatch
    response = self.handle_exception(exc)
  File "E:\Python\Python39\lib\site-packages\rest_framework\views.py", line 469, in handle_exception
    self.raise_uncaught_exception(exc)
  File "E:\Python\Python39\lib\site-packages\rest_framework\views.py", line 480, in raise_uncaught_exception
    raise exc
  File "E:\Python\Python39\lib\site-packages\rest_framework\views.py", line 497, in dispatch
    self.initial(request, *args, **kwargs)
  File "E:\Python\Python39\lib\site-packages\rest_framework\views.py", line 414, in initial
    self.perform_authentication(request)
  File "E:\Python\Python39\lib\site-packages\rest_framework\views.py", line 324, in perform_authentication
    request.user
  File "E:\Python\Python39\lib\site-packages\rest_framework\request.py", line 227, in user
    self._authenticate()
  File "E:\Python\Python39\lib\site-packages\rest_framework\request.py", line 390, in _authenticate
    self._not_authenticated()
  File "E:\Python\Python39\lib\site-packages\rest_framework\request.py", line 400, in _not_authenticated
    if api_settings.UNAUTHENTICATED_USER:
  File "E:\Python\Python39\lib\site-packages\rest_framework\settings.py", line 225, in __getattr__
    val = perform_import(val, attr)
  File "E:\Python\Python39\lib\site-packages\rest_framework\settings.py", line 166, in perform_import
    return import_from_string(val, setting_name)
  File "E:\Python\Python39\lib\site-packages\rest_framework\settings.py", line 177, in import_from_string
    return import_string(val)
  File "E:\Python\Python39\lib\site-packages\django\utils\module_loading.py", line 17, in import_string
    module = import_module(module_path)
  File "E:\Python\Python39\lib\importlib\__init__.py", line 127, in import_module
    return _bootstrap._gcd_import(name[level:], package, level)
  File "<frozen importlib._bootstrap>", line 1030, in _gcd_import
  File "<frozen importlib._bootstrap>", line 1007, in _find_and_load
  File "<frozen importlib._bootstrap>", line 986, in _find_and_load_unlocked
  File "<frozen importlib._bootstrap>", line 680, in _load_unlocked
  File "<frozen importlib._bootstrap_external>", line 850, in exec_module
  File "<frozen importlib._bootstrap>", line 228, in _call_with_frames_removed
  File "E:\Python\Python39\lib\site-packages\django\contrib\auth\models.py", line 35, in <module>
    class Permission(models.Model):
  File "E:\Python\Python39\lib\site-packages\django\db\models\base.py", line 113, in __new__
    raise RuntimeError(
RuntimeError: Model class django.contrib.auth.models.Permission doesn't declare an explicit app_label and isn't in an application in INSTALLED_APPS.
| 500 | 0.05s | 127.0.0.1       | GET  | /swagger/ |
| 200 | 0.01s | 127.0.0.1       | GET  | /swagger/ |
| 404 | 0.01s | 127.0.0.1       | GET  | /static/drf-yasg/style.css |
Not Found: /static/drf-yasg/style.css
| 404 | 0.01s | 127.0.0.1       | GET  | /static/drf-yasg/swagger-ui-dist/swagger-ui.css |
Not Found: /static/drf-yasg/swagger-ui-dist/swagger-ui.css
| 404 | 0.03s | 127.0.0.1       | GET  | /static/drf-yasg/swagger-ui-dist/swagger-ui-standalone-preset.js |
Not Found: /static/drf-yasg/swagger-ui-dist/swagger-ui-standalone-preset.js
| 404 | 0.04s | 127.0.0.1       | GET  | /static/drf-yasg/swagger-ui-dist/swagger-ui-bundle.js |
Not Found: /static/drf-yasg/swagger-ui-dist/swagger-ui-bundle.js
| 404 | 0.08s | 127.0.0.1       | GET  | /static/drf-yasg/insQ.min.js |
Not Found: /static/drf-yasg/insQ.min.js
| 404 | 0.07s | 127.0.0.1       | GET  | /static/drf-yasg/url-polyfill.min.js |
Not Found: /static/drf-yasg/url-polyfill.min.js
| 404 | 0.07s | 127.0.0.1       | GET  | /static/drf-yasg/immutable.min.js |
Not Found: /static/drf-yasg/immutable.min.js
| 404 | 0.07s | 127.0.0.1       | GET  | /static/drf-yasg/swagger-ui-init.js |
Not Found: /static/drf-yasg/swagger-ui-init.js
| 404 | 0.02s | 127.0.0.1       | GET  | /static/drf-yasg/swagger-ui-dist/swagger-ui-standalone-preset.js |
Not Found: /static/drf-yasg/swagger-ui-dist/swagger-ui-standalone-preset.js
| 404 | 0.01s | 127.0.0.1       | GET  | /static/drf-yasg/insQ.min.js |
Not Found: /static/drf-yasg/insQ.min.js
| 404 | 0.00s | 127.0.0.1       | GET  | /static/drf-yasg/immutable.min.js |
Not Found: /static/drf-yasg/immutable.min.js
| 404 | 0.00s | 127.0.0.1       | GET  | /static/drf-yasg/url-polyfill.min.js |
Not Found: /static/drf-yasg/url-polyfill.min.js
| 404 | 0.01s | 127.0.0.1       | GET  | /static/drf-yasg/swagger-ui-init.js |
Not Found: /static/drf-yasg/swagger-ui-init.js
| 404 | 0.01s | 127.0.0.1       | GET  | /static/drf-yasg/swagger-ui-dist/favicon-32x32.png |
Not Found: /static/drf-yasg/swagger-ui-dist/favicon-32x32.png
| 404 | 0.02s | 127.0.0.1       | GET  | /static/drf-yasg/swagger-ui-dist/swagger-ui-bundle.js |
Not Found: /static/drf-yasg/swagger-ui-dist/swagger-ui-bundle.js
| 404 | 0.02s | 127.0.0.1       | GET  | /static/drf-yasg/swagger-ui-dist/swagger-ui-standalone-preset.js |
Not Found: /static/drf-yasg/swagger-ui-dist/swagger-ui-standalone-preset.js
| 404 | 0.02s | 127.0.0.1       | GET  | /static/drf-yasg/url-polyfill.min.js |
Not Found: /static/drf-yasg/url-polyfill.min.js
| 404 | 0.02s | 127.0.0.1       | GET  | /static/drf-yasg/immutable.min.js |
Not Found: /static/drf-yasg/immutable.min.js
| 404 | 0.02s | 127.0.0.1       | GET  | /static/drf-yasg/insQ.min.js |
Not Found: /static/drf-yasg/insQ.min.js
| 404 | 0.02s | 127.0.0.1       | GET  | /static/drf-yasg/swagger-ui-init.js |
Not Found: /static/drf-yasg/swagger-ui-init.js
| 404 | 0.00s | 127.0.0.1       | GET  | /accounts/login/ |
Not Found: /accounts/login/
| 404 | 0.00s | 127.0.0.1       | GET  | /swagger/index.html |
Not Found: /swagger/index.html
| 404 | 0.01s | 127.0.0.1       | GET  | /swagger/index.html |
Not Found: /swagger/index.html
| 404 | 0.01s | 127.0.0.1       | GET  | /favicon.ico |
Not Found: /favicon.ico
Internal Server Error: /swagger/
Traceback (most recent call last):
  File "E:\Python\Python39\lib\site-packages\django\core\handlers\exception.py", line 47, in inner
    response = get_response(request)
  File "E:\Python\Python39\lib\site-packages\django\core\handlers\base.py", line 181, in _get_response
    response = wrapped_callback(request, *callback_args, **callback_kwargs)
  File "E:\Python\Python39\lib\site-packages\django\views\decorators\csrf.py", line 54, in wrapped_view
    return view_func(*args, **kwargs)
  File "E:\Python\Python39\lib\site-packages\django\views\generic\base.py", line 70, in view
    return self.dispatch(request, *args, **kwargs)
  File "E:\Python\Python39\lib\site-packages\rest_framework\views.py", line 509, in dispatch
    response = self.handle_exception(exc)
  File "E:\Python\Python39\lib\site-packages\rest_framework\views.py", line 469, in handle_exception
    self.raise_uncaught_exception(exc)
  File "E:\Python\Python39\lib\site-packages\rest_framework\views.py", line 480, in raise_uncaught_exception
    raise exc
  File "E:\Python\Python39\lib\site-packages\rest_framework\views.py", line 497, in dispatch
    self.initial(request, *args, **kwargs)
  File "E:\Python\Python39\lib\site-packages\rest_framework\views.py", line 414, in initial
    self.perform_authentication(request)
  File "E:\Python\Python39\lib\site-packages\rest_framework\views.py", line 324, in perform_authentication
    request.user
  File "E:\Python\Python39\lib\site-packages\rest_framework\request.py", line 227, in user
    self._authenticate()
  File "E:\Python\Python39\lib\site-packages\rest_framework\request.py", line 390, in _authenticate
    self._not_authenticated()
  File "E:\Python\Python39\lib\site-packages\rest_framework\request.py", line 400, in _not_authenticated
    if api_settings.UNAUTHENTICATED_USER:
  File "E:\Python\Python39\lib\site-packages\rest_framework\settings.py", line 225, in __getattr__
    val = perform_import(val, attr)
  File "E:\Python\Python39\lib\site-packages\rest_framework\settings.py", line 166, in perform_import
    return import_from_string(val, setting_name)
  File "E:\Python\Python39\lib\site-packages\rest_framework\settings.py", line 177, in import_from_string
    return import_string(val)
  File "E:\Python\Python39\lib\site-packages\django\utils\module_loading.py", line 17, in import_string
    module = import_module(module_path)
  File "E:\Python\Python39\lib\importlib\__init__.py", line 127, in import_module
    return _bootstrap._gcd_import(name[level:], package, level)
  File "<frozen importlib._bootstrap>", line 1030, in _gcd_import
  File "<frozen importlib._bootstrap>", line 1007, in _find_and_load
  File "<frozen importlib._bootstrap>", line 986, in _find_and_load_unlocked
  File "<frozen importlib._bootstrap>", line 680, in _load_unlocked
  File "<frozen importlib._bootstrap_external>", line 850, in exec_module
  File "<frozen importlib._bootstrap>", line 228, in _call_with_frames_removed
  File "E:\Python\Python39\lib\site-packages\django\contrib\auth\models.py", line 5, in <module>
    from django.contrib.contenttypes.models import ContentType
  File "E:\Python\Python39\lib\site-packages\django\contrib\contenttypes\models.py", line 133, in <module>
    class ContentType(models.Model):
  File "E:\Python\Python39\lib\site-packages\django\db\models\base.py", line 113, in __new__
    raise RuntimeError(
RuntimeError: Model class django.contrib.contenttypes.models.ContentType doesn't declare an explicit app_label and isn't in an application in INSTALLED_APPS.
| 500 | 0.06s | 127.0.0.1       | GET  | /swagger/ |
| 404 | 0.01s | 127.0.0.1       | GET  | /dos |
Not Found: /dos
| 404 | 0.01s | 127.0.0.1       | GET  | /favicon.ico |
Not Found: /favicon.ico
| 301 | 0.00s | 127.0.0.1       | GET  | /docs |
Internal Server Error: /docs/
Traceback (most recent call last):
  File "E:\Python\Python39\lib\site-packages\django\core\handlers\exception.py", line 47, in inner
    response = get_response(request)
  File "E:\Python\Python39\lib\site-packages\django\core\handlers\base.py", line 181, in _get_response
    response = wrapped_callback(request, *callback_args, **callback_kwargs)
  File "E:\Python\Python39\lib\site-packages\django\views\decorators\csrf.py", line 54, in wrapped_view
    return view_func(*args, **kwargs)
  File "E:\Python\Python39\lib\site-packages\django\views\generic\base.py", line 70, in view
    return self.dispatch(request, *args, **kwargs)
  File "E:\Python\Python39\lib\site-packages\rest_framework\views.py", line 509, in dispatch
    response = self.handle_exception(exc)
  File "E:\Python\Python39\lib\site-packages\rest_framework\schemas\views.py", line 48, in handle_exception
    return super().handle_exception(exc)
  File "E:\Python\Python39\lib\site-packages\rest_framework\views.py", line 469, in handle_exception
    self.raise_uncaught_exception(exc)
  File "E:\Python\Python39\lib\site-packages\rest_framework\views.py", line 480, in raise_uncaught_exception
    raise exc
  File "E:\Python\Python39\lib\site-packages\rest_framework\views.py", line 497, in dispatch
    self.initial(request, *args, **kwargs)
  File "E:\Python\Python39\lib\site-packages\rest_framework\views.py", line 414, in initial
    self.perform_authentication(request)
  File "E:\Python\Python39\lib\site-packages\rest_framework\views.py", line 324, in perform_authentication
    request.user
  File "E:\Python\Python39\lib\site-packages\rest_framework\request.py", line 227, in user
    self._authenticate()
  File "E:\Python\Python39\lib\site-packages\rest_framework\request.py", line 390, in _authenticate
    self._not_authenticated()
  File "E:\Python\Python39\lib\site-packages\rest_framework\request.py", line 400, in _not_authenticated
    if api_settings.UNAUTHENTICATED_USER:
  File "E:\Python\Python39\lib\site-packages\rest_framework\settings.py", line 225, in __getattr__
    val = perform_import(val, attr)
  File "E:\Python\Python39\lib\site-packages\rest_framework\settings.py", line 166, in perform_import
    return import_from_string(val, setting_name)
  File "E:\Python\Python39\lib\site-packages\rest_framework\settings.py", line 177, in import_from_string
    return import_string(val)
  File "E:\Python\Python39\lib\site-packages\django\utils\module_loading.py", line 17, in import_string
    module = import_module(module_path)
  File "E:\Python\Python39\lib\importlib\__init__.py", line 127, in import_module
    return _bootstrap._gcd_import(name[level:], package, level)
  File "<frozen importlib._bootstrap>", line 1030, in _gcd_import
  File "<frozen importlib._bootstrap>", line 1007, in _find_and_load
  File "<frozen importlib._bootstrap>", line 986, in _find_and_load_unlocked
  File "<frozen importlib._bootstrap>", line 680, in _load_unlocked
  File "<frozen importlib._bootstrap_external>", line 850, in exec_module
  File "<frozen importlib._bootstrap>", line 228, in _call_with_frames_removed
  File "E:\Python\Python39\lib\site-packages\django\contrib\auth\models.py", line 5, in <module>
    from django.contrib.contenttypes.models import ContentType
  File "E:\Python\Python39\lib\site-packages\django\contrib\contenttypes\models.py", line 133, in <module>
    class ContentType(models.Model):
  File "E:\Python\Python39\lib\site-packages\django\db\models\base.py", line 113, in __new__
    raise RuntimeError(
RuntimeError: Model class django.contrib.contenttypes.models.ContentType doesn't declare an explicit app_label and isn't in an application in INSTALLED_APPS.
| 500 | 0.07s | 127.0.0.1       | GET  | /docs/ |
Internal Server Error: /docs/
Traceback (most recent call last):
  File "E:\Python\Python39\lib\site-packages\django\core\handlers\exception.py", line 47, in inner
    response = get_response(request)
  File "E:\Python\Python39\lib\site-packages\django\core\handlers\base.py", line 181, in _get_response
    response = wrapped_callback(request, *callback_args, **callback_kwargs)
  File "E:\Python\Python39\lib\site-packages\django\views\decorators\csrf.py", line 54, in wrapped_view
    return view_func(*args, **kwargs)
  File "E:\Python\Python39\lib\site-packages\django\views\generic\base.py", line 70, in view
    return self.dispatch(request, *args, **kwargs)
  File "E:\Python\Python39\lib\site-packages\rest_framework\views.py", line 509, in dispatch
    response = self.handle_exception(exc)
  File "E:\Python\Python39\lib\site-packages\rest_framework\schemas\views.py", line 48, in handle_exception
    return super().handle_exception(exc)
  File "E:\Python\Python39\lib\site-packages\rest_framework\views.py", line 469, in handle_exception
    self.raise_uncaught_exception(exc)
  File "E:\Python\Python39\lib\site-packages\rest_framework\views.py", line 480, in raise_uncaught_exception
    raise exc
  File "E:\Python\Python39\lib\site-packages\rest_framework\views.py", line 497, in dispatch
    self.initial(request, *args, **kwargs)
  File "E:\Python\Python39\lib\site-packages\rest_framework\views.py", line 414, in initial
    self.perform_authentication(request)
  File "E:\Python\Python39\lib\site-packages\rest_framework\views.py", line 324, in perform_authentication
    request.user
  File "E:\Python\Python39\lib\site-packages\rest_framework\request.py", line 227, in user
    self._authenticate()
  File "E:\Python\Python39\lib\site-packages\rest_framework\request.py", line 390, in _authenticate
    self._not_authenticated()
  File "E:\Python\Python39\lib\site-packages\rest_framework\request.py", line 400, in _not_authenticated
    if api_settings.UNAUTHENTICATED_USER:
  File "E:\Python\Python39\lib\site-packages\rest_framework\settings.py", line 225, in __getattr__
    val = perform_import(val, attr)
  File "E:\Python\Python39\lib\site-packages\rest_framework\settings.py", line 166, in perform_import
    return import_from_string(val, setting_name)
  File "E:\Python\Python39\lib\site-packages\rest_framework\settings.py", line 177, in import_from_string
    return import_string(val)
  File "E:\Python\Python39\lib\site-packages\django\utils\module_loading.py", line 17, in import_string
    module = import_module(module_path)
  File "E:\Python\Python39\lib\importlib\__init__.py", line 127, in import_module
    return _bootstrap._gcd_import(name[level:], package, level)
  File "<frozen importlib._bootstrap>", line 1030, in _gcd_import
  File "<frozen importlib._bootstrap>", line 1007, in _find_and_load
  File "<frozen importlib._bootstrap>", line 986, in _find_and_load_unlocked
  File "<frozen importlib._bootstrap>", line 680, in _load_unlocked
  File "<frozen importlib._bootstrap_external>", line 850, in exec_module
  File "<frozen importlib._bootstrap>", line 228, in _call_with_frames_removed
  File "E:\Python\Python39\lib\site-packages\django\contrib\auth\models.py", line 5, in <module>
    from django.contrib.contenttypes.models import ContentType
  File "E:\Python\Python39\lib\site-packages\django\contrib\contenttypes\models.py", line 133, in <module>
    class ContentType(models.Model):
  File "E:\Python\Python39\lib\site-packages\django\db\models\base.py", line 113, in __new__
    raise RuntimeError(
RuntimeError: Model class django.contrib.contenttypes.models.ContentType doesn't declare an explicit app_label and isn't in an application in INSTALLED_APPS.
| 500 | 0.05s | 127.0.0.1       | GET  | /docs/ |
| 404 | 0.00s | 127.0.0.1       | GET  | /favicon.ico |
Not Found: /favicon.ico
| 200 | 0.00s | 127.0.0.1       | OPTIONS | /settings/getdb |
| 200 | 0.00s | 127.0.0.1       | POST | /settings/getdb |
| 200 | 0.00s | 127.0.0.1       | POST | /settings/getdb |
| 200 | 0.00s | 127.0.0.1       | OPTIONS | /settings/backupsdb |
| 200 | 0.04s | 127.0.0.1       | GET  | /settings/backupsdb |
| 200 | 0.00s | 127.0.0.1       | POST | /settings/getdb |
| 200 | 0.00s | 127.0.0.1       | POST | /settings/getdb |
| 200 | 0.00s | 127.0.0.1       | OPTIONS | /home/getsentence |
| 200 | 0.00s | 127.0.0.1       | OPTIONS | /home/get |
| 200 | 0.04s | 127.0.0.1       | GET  | /home/get |
| 404 | 0.03s | 127.0.0.1       | GET  | //image/qjcrs.png |
Not Found: //image/qjcrs.png
| 200 | 0.00s | 127.0.0.1       | POST | /settings/getdb |
| 200 | 0.14s | 127.0.0.1       | GET  | /static/sentence/sentence.txt |
| 200 | 4.27s | 127.0.0.1       | GET  | /home/getsentence |
| 200 | 0.00s | 127.0.0.1       | OPTIONS | /settings/downdb |
| 200 | 0.00s | 127.0.0.1       | POST | /settings/downdb |
| 200 | 0.00s | 127.0.0.1       | OPTIONS | /settings/deletedb |
| 200 | 0.00s | 127.0.0.1       | POST | /settings/deletedb |
| 200 | 0.00s | 127.0.0.1       | POST | /settings/getdb |
| 200 | 0.00s | 127.0.0.1       | POST | /settings/deletedb |
| 200 | 0.00s | 127.0.0.1       | POST | /settings/getdb |
| 200 | 0.00s | 127.0.0.1       | POST | /settings/deletedb |
| 200 | 0.00s | 127.0.0.1       | POST | /settings/getdb |
| 200 | 0.00s | 127.0.0.1       | POST | /settings/deletedb |
| 200 | 0.00s | 127.0.0.1       | POST | /settings/getdb |
| 200 | 0.00s | 127.0.0.1       | OPTIONS | /auth/login |
| 200 | 0.06s | 127.0.0.1       | POST | /auth/login |
| 200 | 0.00s | 127.0.0.1       | OPTIONS | /home/getsentence |
| 200 | 0.00s | 127.0.0.1       | OPTIONS | /home/get |
| 200 | 0.02s | 127.0.0.1       | GET  | /home/get |
| 404 | 0.01s | 127.0.0.1       | GET  | //image/qjcrs.png |
Not Found: //image/qjcrs.png
| 200 | 0.13s | 127.0.0.1       | GET  | /static/sentence/sentence.txt |
| 200 | 4.22s | 127.0.0.1       | GET  | /home/getsentence |
| 200 | 0.00s | 127.0.0.1       | OPTIONS | /food/get |
| 200 | 0.01s | 127.0.0.1       | GET  | /food/get |
| 404 | 0.00s | 127.0.0.1       | GET  | //image/qjcrs.png |
Not Found: //image/qjcrs.png
| 200 | 0.00s | 127.0.0.1       | OPTIONS | /food/delete/6 |
| 200 | 0.01s | 127.0.0.1       | DELETE | /food/delete/6 |
| 200 | 0.00s | 127.0.0.1       | DELETE | /food/delete/6 |
| 200 | 0.00s | 127.0.0.1       | OPTIONS | /order/get |
| 200 | 0.01s | 127.0.0.1       | GET  | /order/get |
| 200 | 0.01s | 127.0.0.1       | GET  | /food/get |
| 404 | 0.01s | 127.0.0.1       | GET  | //image/qjcrs.png |
Not Found: //image/qjcrs.png
| 200 | 0.01s | 127.0.0.1       | DELETE | /food/delete/6 |
| 200 | 0.01s | 127.0.0.1       | GET  | /food/get |
| 404 | 0.01s | 127.0.0.1       | GET  | //image/qjcrs.png |
Not Found: //image/qjcrs.png
| 200 | 0.00s | 127.0.0.1       | OPTIONS | /food/detail |
| 200 | 0.00s | 127.0.0.1       | GET  | /food/detail |
| 404 | 0.00s | 127.0.0.1       | GET  | //image/qjcrs.png |
Not Found: //image/qjcrs.png
| 404 | 0.00s | 127.0.0.1       | GET  | //video/qjcrs.mp4 |
Not Found: //video/qjcrs.mp4
| 200 | 0.00s | 127.0.0.1       | GET  | /food/detail |
| 404 | 0.01s | 127.0.0.1       | GET  | //video/qjcrs.mp4 |
Not Found: //video/qjcrs.mp4
| 200 | 0.01s | 127.0.0.1       | GET  | /order/get |
| 200 | 0.01s | 127.0.0.1       | GET  | /food/get |
| 200 | 0.00s | 127.0.0.1       | GET  | /food/detail |
| 200 | 0.00s | 127.0.0.1       | OPTIONS | /food/update |
| 200 | 0.01s | 127.0.0.1       | PUT  | /food/update |
| 200 | 0.00s | 127.0.0.1       | GET  | /food/get |
| 200 | 0.00s | 127.0.0.1       | GET  | /order/get |
| 200 | 0.00s | 127.0.0.1       | OPTIONS | /order/delete/3 |
| 200 | 0.00s | 127.0.0.1       | DELETE | /order/delete/3 |
| 200 | 0.01s | 127.0.0.1       | GET  | /order/get |
| 200 | 0.00s | 127.0.0.1       | OPTIONS | /order/delete/4 |
| 200 | 0.00s | 127.0.0.1       | DELETE | /order/delete/4 |
| 200 | 0.01s | 127.0.0.1       | GET  | /order/get |
| 200 | 0.00s | 127.0.0.1       | OPTIONS | /order/delete/5 |
| 200 | 0.01s | 127.0.0.1       | DELETE | /order/delete/5 |
| 200 | 0.01s | 127.0.0.1       | GET  | /order/get |
| 200 | 0.00s | 127.0.0.1       | OPTIONS | /order/delete/6 |
| 200 | 0.00s | 127.0.0.1       | DELETE | /order/delete/6 |
| 200 | 0.01s | 127.0.0.1       | GET  | /order/get |
| 200 | 0.00s | 127.0.0.1       | OPTIONS | /order/delete/8 |
| 200 | 0.00s | 127.0.0.1       | DELETE | /order/delete/8 |
| 200 | 0.00s | 127.0.0.1       | GET  | /order/get |
| 200 | 0.00s | 127.0.0.1       | OPTIONS | /order/delete/9 |
| 200 | 0.01s | 127.0.0.1       | DELETE | /order/delete/9 |
| 200 | 0.01s | 127.0.0.1       | GET  | /order/get |
| 200 | 0.00s | 127.0.0.1       | OPTIONS | /order/delete/10 |
| 200 | 0.01s | 127.0.0.1       | DELETE | /order/delete/10 |
| 200 | 0.01s | 127.0.0.1       | GET  | /order/get |
| 200 | 0.00s | 127.0.0.1       | OPTIONS | /order/delete/11 |
| 200 | 0.01s | 127.0.0.1       | DELETE | /order/delete/11 |
| 200 | 0.01s | 127.0.0.1       | GET  | /order/get |
| 200 | 0.01s | 127.0.0.1       | GET  | /food/get |
| 200 | 0.01s | 127.0.0.1       | GET  | /order/get |
| 200 | 0.00s | 127.0.0.1       | OPTIONS | /food/get |
| 200 | 0.01s | 127.0.0.1       | GET  | /food/get |
| 200 | 0.00s | 127.0.0.1       | OPTIONS | /order/add |
| 200 | 0.00s | 127.0.0.1       | POST | /order/add |
| 200 | 0.01s | 127.0.0.1       | POST | /order/add |
| 200 | 0.00s | 127.0.0.1       | POST | /order/add |
| 200 | 0.01s | 127.0.0.1       | POST | /order/add |
| 200 | 0.00s | 127.0.0.1       | POST | /order/add |
| 200 | 0.00s | 127.0.0.1       | POST | /order/add |
| 200 | 0.00s | 127.0.0.1       | POST | /order/add |
| 200 | 0.00s | 127.0.0.1       | POST | /order/add |
| 200 | 0.01s | 127.0.0.1       | GET  | /order/get |
| 200 | 0.01s | 127.0.0.1       | GET  | /food/get |
| 200 | 0.01s | 127.0.0.1       | GET  | /food/get |
| 200 | 0.01s | 127.0.0.1       | GET  | /order/get |
| 200 | 0.01s | 127.0.0.1       | GET  | /food/get |
| 200 | 0.00s | 127.0.0.1       | OPTIONS | /role/get |
| 200 | 0.01s | 127.0.0.1       | GET  | /role/get |
| 200 | 0.00s | 127.0.0.1       | OPTIONS | /user/get |
| 200 | 0.01s | 127.0.0.1       | GET  | /user/get |
| 200 | 0.01s | 127.0.0.1       | GET  | /food/get |
| 200 | 0.00s | 127.0.0.1       | GET  | /food/detail |
| 200 | 0.01s | 127.0.0.1       | GET  | /order/get |
| 200 | 0.01s | 127.0.0.1       | GET  | /user/get |
| 200 | 0.02s | 127.0.0.1       | GET  | /role/get |
| 200 | 0.01s | 127.0.0.1       | GET  | /user/get |
| 200 | 0.00s | 127.0.0.1       | OPTIONS | /user/detail |
| 200 | 0.00s | 127.0.0.1       | GET  | /user/detail |
| 200 | 0.00s | 127.0.0.1       | OPTIONS | /role/get |
| 200 | 0.00s | 127.0.0.1       | GET  | /role/get |
| 200 | 0.01s | 127.0.0.1       | GET  | /role/get |
| 200 | 0.01s | 127.0.0.1       | GET  | /food/get |
| 200 | 0.00s | 127.0.0.1       | OPTIONS | /food/detail |
| 200 | 0.00s | 127.0.0.1       | GET  | /food/detail |
| 200 | 0.00s | 127.0.0.1       | GET  | /food/detail |
| 200 | 0.01s | 127.0.0.1       | PUT  | /food/update |
| 200 | 0.01s | 127.0.0.1       | GET  | /food/get |
| 200 | 0.00s | 127.0.0.1       | GET  | /food/detail |
| 200 | 0.01s | 127.0.0.1       | GET  | /food/detail |
| 200 | 0.00s | 127.0.0.1       | GET  | /order/get |
| 200 | 0.01s | 127.0.0.1       | GET  | /food/get |
| 200 | 0.02s | 127.0.0.1       | GET  | /order/get |
| 200 | 0.01s | 127.0.0.1       | GET  | /food/get |
| 200 | 0.01s | 127.0.0.1       | GET  | /role/get |
| 200 | 0.01s | 127.0.0.1       | GET  | /user/get |
| 200 | 0.01s | 127.0.0.1       | GET  | /food/get |
| 200 | 0.01s | 127.0.0.1       | GET  | /role/get |
| 200 | 0.01s | 127.0.0.1       | GET  | /user/get |
| 200 | 0.02s | 127.0.0.1       | GET  | /role/get |
| 200 | 0.01s | 127.0.0.1       | GET  | /user/get |
Internal Server Error: /food/get
Traceback (most recent call last):
  File "E:\Python\Python39\lib\site-packages\django\core\handlers\exception.py", line 47, in inner
    response = get_response(request)
  File "E:\Python\Python39\lib\site-packages\django\core\handlers\base.py", line 181, in _get_response
    response = wrapped_callback(request, *callback_args, **callback_kwargs)
  File "E:\Python\Python39\lib\site-packages\django\views\decorators\http.py", line 40, in inner
    return func(request, *args, **kwargs)
  File "D:\A7\Desktop\Vulnerabilities_Server\Python_Server\src\apps\food\views.py", line 31, in food_get
    foodlisttmp.append({'id':foodtmp.id, 'user': foodtmp.user.name, 'user_id': foodtmp.user.id, 'foodname': foodtmp.foodname, 'price':foodtmp.price, 'foodicon':foodtmp.foodicon, 'foodprocedure':foodtmp.foodprocedure, 'video':foodtmp.video, 'remarks':foodtmp.remarks, 'created_at':foodtmp.created_at, 'updated_at':foodtmp.updated_at})
AttributeError: 'User' object has no attribute 'name'
| 500 | 0.04s | 127.0.0.1       | GET  | /food/get |
| 200 | 0.01s | 127.0.0.1       | GET  | /order/get |
Internal Server Error: /food/get
Traceback (most recent call last):
  File "E:\Python\Python39\lib\site-packages\django\core\handlers\exception.py", line 47, in inner
    response = get_response(request)
  File "E:\Python\Python39\lib\site-packages\django\core\handlers\base.py", line 181, in _get_response
    response = wrapped_callback(request, *callback_args, **callback_kwargs)
  File "E:\Python\Python39\lib\site-packages\django\views\decorators\http.py", line 40, in inner
    return func(request, *args, **kwargs)
  File "D:\A7\Desktop\Vulnerabilities_Server\Python_Server\src\apps\food\views.py", line 31, in food_get
    foodlisttmp.append({'id':foodtmp.id, 'user': foodtmp.user.name, 'user_id': foodtmp.user.id, 'foodname': foodtmp.foodname, 'price':foodtmp.price, 'foodicon':foodtmp.foodicon, 'foodprocedure':foodtmp.foodprocedure, 'video':foodtmp.video, 'remarks':foodtmp.remarks, 'created_at':foodtmp.created_at, 'updated_at':foodtmp.updated_at})
AttributeError: 'User' object has no attribute 'name'
| 500 | 0.02s | 127.0.0.1       | GET  | /food/get |
| 200 | 0.01s | 127.0.0.1       | GET  | /order/get |
Internal Server Error: /food/get
Traceback (most recent call last):
  File "E:\Python\Python39\lib\site-packages\django\core\handlers\exception.py", line 47, in inner
    response = get_response(request)
  File "E:\Python\Python39\lib\site-packages\django\core\handlers\base.py", line 181, in _get_response
    response = wrapped_callback(request, *callback_args, **callback_kwargs)
  File "E:\Python\Python39\lib\site-packages\django\views\decorators\http.py", line 40, in inner
    return func(request, *args, **kwargs)
  File "D:\A7\Desktop\Vulnerabilities_Server\Python_Server\src\apps\food\views.py", line 32, in food_get
    foodlisttmp.append({'id':foodtmp.id, 'user': foodtmp.user.name, 'user_id': foodtmp.user.id, 'foodname': foodtmp.foodname, 'price':foodtmp.price, 'foodicon':foodtmp.foodicon, 'foodprocedure':foodtmp.foodprocedure, 'video':foodtmp.video, 'remarks':foodtmp.remarks, 'created_at':foodtmp.created_at, 'updated_at':foodtmp.updated_at})
AttributeError: 'User' object has no attribute 'name'
| 500 | 0.04s | 127.0.0.1       | GET  | /food/get |
| 200 | 0.01s | 127.0.0.1       | GET  | /order/get |
Internal Server Error: /food/get
Traceback (most recent call last):
  File "E:\Python\Python39\lib\site-packages\django\core\handlers\exception.py", line 47, in inner
    response = get_response(request)
  File "E:\Python\Python39\lib\site-packages\django\core\handlers\base.py", line 181, in _get_response
    response = wrapped_callback(request, *callback_args, **callback_kwargs)
  File "E:\Python\Python39\lib\site-packages\django\views\decorators\http.py", line 40, in inner
    return func(request, *args, **kwargs)
  File "D:\A7\Desktop\Vulnerabilities_Server\Python_Server\src\apps\food\views.py", line 31, in food_get
    foodlisttmp.append({'id':foodtmp.id, 'user': foodtmp.user.name, 'user_id': foodtmp.user.id, 'foodname': foodtmp.foodname, 'price':foodtmp.price, 'foodicon':foodtmp.foodicon, 'foodprocedure':foodtmp.foodprocedure, 'video':foodtmp.video, 'remarks':foodtmp.remarks, 'created_at':foodtmp.created_at, 'updated_at':foodtmp.updated_at})
AttributeError: 'User' object has no attribute 'name'
| 500 | 0.04s | 127.0.0.1       | GET  | /food/get |
| 200 | 0.01s | 127.0.0.1       | GET  | /order/get |
| 200 | 0.01s | 127.0.0.1       | GET  | /food/get |
| 200 | 0.01s | 127.0.0.1       | GET  | /order/get |
| 200 | 0.01s | 127.0.0.1       | GET  | /food/get |
| 200 | 0.01s | 127.0.0.1       | GET  | /order/get |
| 200 | 0.01s | 127.0.0.1       | GET  | /food/get |
| 200 | 0.01s | 127.0.0.1       | GET  | /order/get |
| 200 | 0.00s | 127.0.0.1       | GET  | /role/get |
| 200 | 0.01s | 127.0.0.1       | GET  | /user/get |
| 200 | 0.01s | 127.0.0.1       | GET  | /role/get |
| 200 | 0.00s | 127.0.0.1       | OPTIONS | /auth/loginout |
| 200 | 0.00s | 127.0.0.1       | GET  | /auth/loginout |
| 200 | 0.03s | 127.0.0.1       | POST | /auth/login |
| 200 | 0.01s | 127.0.0.1       | GET  | /home/get |
| 200 | 0.00s | 127.0.0.1       | OPTIONS | /settings/getdb |
| 200 | 0.00s | 127.0.0.1       | POST | /settings/getdb |
| 200 | 0.15s | 127.0.0.1       | GET  | /static/sentence/sentence.txt |
| 200 | 4.41s | 127.0.0.1       | GET  | /home/getsentence |
| 200 | 0.01s | 127.0.0.1       | GET  | /food/get |
| 200 | 0.01s | 127.0.0.1       | GET  | /food/detail |
| 200 | 0.01s | 127.0.0.1       | GET  | /order/get |
| 200 | 0.01s | 127.0.0.1       | GET  | /food/get |
| 200 | 0.01s | 127.0.0.1       | GET  | /order/get |
| 200 | 0.01s | 127.0.0.1       | GET  | /food/get |
| 200 | 0.01s | 127.0.0.1       | GET  | /food/detail |
| 200 | 0.01s | 127.0.0.1       | GET  | /order/get |
| 200 | 0.00s | 127.0.0.1       | GET  | /food/get |
| 200 | 0.00s | 127.0.0.1       | GET  | /food/detail |
| 200 | 0.00s | 127.0.0.1       | POST | /settings/getdb |
| 200 | 0.01s | 127.0.0.1       | GET  | /user/get |
| 200 | 0.01s | 127.0.0.1       | GET  | /role/get |
| 200 | 0.00s | 127.0.0.1       | GET  | /auth/loginout |
| 200 | 0.03s | 127.0.0.1       | POST | /auth/login |
| 200 | 0.01s | 127.0.0.1       | GET  | /home/get |
| 200 | 0.01s | 127.0.0.1       | GET  | /food/get |
| 200 | 0.00s | 127.0.0.1       | GET  | /food/detail |
| 200 | 0.13s | 127.0.0.1       | GET  | /static/sentence/sentence.txt |
| 200 | 4.24s | 127.0.0.1       | GET  | /home/getsentence |
| 200 | 0.00s | 127.0.0.1       | GET  | /food/detail |
| 200 | 0.01s | 127.0.0.1       | PUT  | /food/update |
| 200 | 0.01s | 127.0.0.1       | GET  | /food/get |
| 200 | 0.00s | 127.0.0.1       | GET  | /food/detail |
| 200 | 0.01s | 127.0.0.1       | PUT  | /food/update |
| 200 | 0.01s | 127.0.0.1       | GET  | /food/get |
| 200 | 0.00s | 127.0.0.1       | GET  | /food/detail |
| 200 | 0.01s | 127.0.0.1       | PUT  | /food/update |
| 200 | 0.01s | 127.0.0.1       | GET  | /food/get |
| 200 | 0.00s | 127.0.0.1       | GET  | /order/get |
| 200 | 0.01s | 127.0.0.1       | GET  | /food/get |
| 200 | 0.01s | 127.0.0.1       | GET  | /home/get |
| 200 | 0.00s | 127.0.0.1       | GET  | /static/sentence/sentence.txt |
| 200 | 4.10s | 127.0.0.1       | GET  | /home/getsentence |
| 200 | 0.01s | 127.0.0.1       | GET  | /order/get |
| 200 | 0.01s | 127.0.0.1       | GET  | /food/get |
| 200 | 0.01s | 127.0.0.1       | GET  | /home/get |
| 200 | 0.00s | 127.0.0.1       | GET  | /static/sentence/sentence.txt |
| 200 | 4.09s | 127.0.0.1       | GET  | /home/getsentence |
| 200 | 0.00s | 127.0.0.1       | GET  | /auth/loginout |
